2018-05-09 17:55:40,906 ERROR: Exception on /notifications [GET] [in /home/vitaly/microblog/venv/lib/python3.5/site-packages/flask/app.py:1560]
Traceback (most recent call last):
  File "/home/vitaly/microblog/venv/lib/python3.5/site-packages/sqlalchemy/engine/base.py", line 1182, in _execute_context
    context)
  File "/home/vitaly/microblog/venv/lib/python3.5/site-packages/sqlalchemy/engine/default.py", line 470, in do_execute
    cursor.execute(statement, parameters)
  File "/home/vitaly/microblog/venv/lib/python3.5/site-packages/pymysql/cursors.py", line 170, in execute
    result = self._query(query)
  File "/home/vitaly/microblog/venv/lib/python3.5/site-packages/pymysql/cursors.py", line 328, in _query
    conn.query(q)
  File "/home/vitaly/microblog/venv/lib/python3.5/site-packages/pymysql/connections.py", line 893, in query
    self._affected_rows = self._read_query_result(unbuffered=unbuffered)
  File "/home/vitaly/microblog/venv/lib/python3.5/site-packages/pymysql/connections.py", line 1103, in _read_query_result
    result.read()
  File "/home/vitaly/microblog/venv/lib/python3.5/site-packages/pymysql/connections.py", line 1396, in read
    first_packet = self.connection._read_packet()
  File "/home/vitaly/microblog/venv/lib/python3.5/site-packages/pymysql/connections.py", line 1032, in _read_packet
    packet_header = self._read_bytes(4)
  File "/home/vitaly/microblog/venv/lib/python3.5/site-packages/pymysql/connections.py", line 1078, in _read_bytes
    CR.CR_SERVER_LOST, "Lost connection to MySQL server during query")
pymysql.err.OperationalError: (2013, 'Lost connection to MySQL server during query')

The above exception was the direct cause of the following exception:

Traceback (most recent call last):
  File "/home/vitaly/microblog/venv/lib/python3.5/site-packages/flask/app.py", line 1982, in wsgi_app
    response = self.full_dispatch_request()
  File "/home/vitaly/microblog/venv/lib/python3.5/site-packages/flask/app.py", line 1614, in full_dispatch_request
    rv = self.handle_user_exception(e)
  File "/home/vitaly/microblog/venv/lib/python3.5/site-packages/flask/app.py", line 1517, in handle_user_exception
    reraise(exc_type, exc_value, tb)
  File "/home/vitaly/microblog/venv/lib/python3.5/site-packages/flask/_compat.py", line 33, in reraise
    raise value
  File "/home/vitaly/microblog/venv/lib/python3.5/site-packages/flask/app.py", line 1610, in full_dispatch_request
    rv = self.preprocess_request()
  File "/home/vitaly/microblog/venv/lib/python3.5/site-packages/flask/app.py", line 1831, in preprocess_request
    rv = func()
  File "/home/vitaly/microblog/app/main/routes.py", line 16, in before_request
    if current_user.is_authenticated:
  File "/home/vitaly/microblog/venv/lib/python3.5/site-packages/werkzeug/local.py", line 347, in __getattr__
    return getattr(self._get_current_object(), name)
  File "/home/vitaly/microblog/venv/lib/python3.5/site-packages/werkzeug/local.py", line 306, in _get_current_object
    return self.__local()
  File "/home/vitaly/microblog/venv/lib/python3.5/site-packages/flask_login/utils.py", line 26, in <lambda>
    current_user = LocalProxy(lambda: _get_user())
  File "/home/vitaly/microblog/venv/lib/python3.5/site-packages/flask_login/utils.py", line 302, in _get_user
    current_app.login_manager._load_user()
  File "/home/vitaly/microblog/venv/lib/python3.5/site-packages/flask_login/login_manager.py", line 317, in _load_user
    return self.reload_user()
  File "/home/vitaly/microblog/venv/lib/python3.5/site-packages/flask_login/login_manager.py", line 279, in reload_user
    user = self.user_callback(user_id)
  File "/home/vitaly/microblog/app/models.py", line 233, in load_user
    return User.query.get(int(id))
  File "/home/vitaly/microblog/venv/lib/python3.5/site-packages/sqlalchemy/orm/query.py", line 864, in get
    return self._get_impl(ident, loading.load_on_ident)
  File "/home/vitaly/microblog/venv/lib/python3.5/site-packages/sqlalchemy/orm/query.py", line 897, in _get_impl
    return fallback_fn(self, key)
  File "/home/vitaly/microblog/venv/lib/python3.5/site-packages/sqlalchemy/orm/loading.py", line 223, in load_on_ident
    return q.one()
  File "/home/vitaly/microblog/venv/lib/python3.5/site-packages/sqlalchemy/orm/query.py", line 2814, in one
    ret = self.one_or_none()
  File "/home/vitaly/microblog/venv/lib/python3.5/site-packages/sqlalchemy/orm/query.py", line 2784, in one_or_none
    ret = list(self)
  File "/home/vitaly/microblog/venv/lib/python3.5/site-packages/sqlalchemy/orm/query.py", line 2855, in __iter__
    return self._execute_and_instances(context)
  File "/home/vitaly/microblog/venv/lib/python3.5/site-packages/sqlalchemy/orm/query.py", line 2878, in _execute_and_instances
    result = conn.execute(querycontext.statement, self._params)
  File "/home/vitaly/microblog/venv/lib/python3.5/site-packages/sqlalchemy/engine/base.py", line 945, in execute
    return meth(self, multiparams, params)
  File "/home/vitaly/microblog/venv/lib/python3.5/site-packages/sqlalchemy/sql/elements.py", line 263, in _execute_on_connection
    return connection._execute_clauseelement(self, multiparams, params)
  File "/home/vitaly/microblog/venv/lib/python3.5/site-packages/sqlalchemy/engine/base.py", line 1053, in _execute_clauseelement
    compiled_sql, distilled_params
  File "/home/vitaly/microblog/venv/lib/python3.5/site-packages/sqlalchemy/engine/base.py", line 1189, in _execute_context
    context)
  File "/home/vitaly/microblog/venv/lib/python3.5/site-packages/sqlalchemy/engine/base.py", line 1402, in _handle_dbapi_exception
    exc_info
  File "/home/vitaly/microblog/venv/lib/python3.5/site-packages/sqlalchemy/util/compat.py", line 203, in raise_from_cause
    reraise(type(exception), exception, tb=exc_tb, cause=cause)
  File "/home/vitaly/microblog/venv/lib/python3.5/site-packages/sqlalchemy/util/compat.py", line 186, in reraise
    raise value.with_traceback(tb)
  File "/home/vitaly/microblog/venv/lib/python3.5/site-packages/sqlalchemy/engine/base.py", line 1182, in _execute_context
    context)
  File "/home/vitaly/microblog/venv/lib/python3.5/site-packages/sqlalchemy/engine/default.py", line 470, in do_execute
    cursor.execute(statement, parameters)
  File "/home/vitaly/microblog/venv/lib/python3.5/site-packages/pymysql/cursors.py", line 170, in execute
    result = self._query(query)
  File "/home/vitaly/microblog/venv/lib/python3.5/site-packages/pymysql/cursors.py", line 328, in _query
    conn.query(q)
  File "/home/vitaly/microblog/venv/lib/python3.5/site-packages/pymysql/connections.py", line 893, in query
    self._affected_rows = self._read_query_result(unbuffered=unbuffered)
  File "/home/vitaly/microblog/venv/lib/python3.5/site-packages/pymysql/connections.py", line 1103, in _read_query_result
    result.read()
  File "/home/vitaly/microblog/venv/lib/python3.5/site-packages/pymysql/connections.py", line 1396, in read
    first_packet = self.connection._read_packet()
  File "/home/vitaly/microblog/venv/lib/python3.5/site-packages/pymysql/connections.py", line 1032, in _read_packet
    packet_header = self._read_bytes(4)
  File "/home/vitaly/microblog/venv/lib/python3.5/site-packages/pymysql/connections.py", line 1078, in _read_bytes
    CR.CR_SERVER_LOST, "Lost connection to MySQL server during query")
sqlalchemy.exc.OperationalError: (pymysql.err.OperationalError) (2013, 'Lost connection to MySQL server during query') [SQL: 'SELECT user.id AS user_id, user.username AS user_username, user.email AS user_email, user.password_hash AS user_password_hash, user.about_me AS user_about_me, user.last_seen AS user_last_seen, user.token AS user_token, user.token_expiration AS user_token_expiration, user.last_message_read_time AS user_last_message_read_time \nFROM user \nWHERE user.id = %(param_1)s'] [parameters: {'param_1': 1}]
2018-05-10 12:38:16,937 INFO: Microblog startup [in /home/vitaly/microblog/app/__init__.py:89]
2018-05-10 12:38:16,937 INFO: Microblog startup [in /home/vitaly/microblog/app/__init__.py:89]
2018-05-10 12:38:16,937 INFO: Microblog startup [in /home/vitaly/microblog/app/__init__.py:89]
2018-05-10 12:38:16,938 INFO: Microblog startup [in /home/vitaly/microblog/app/__init__.py:89]
2018-05-10 13:07:01,153 INFO: Microblog startup [in /home/vitaly/microblog/app/__init__.py:89]
2018-05-10 13:07:01,154 INFO: Microblog startup [in /home/vitaly/microblog/app/__init__.py:89]
2018-05-10 13:07:01,159 INFO: Microblog startup [in /home/vitaly/microblog/app/__init__.py:89]
2018-05-10 13:07:01,162 INFO: Microblog startup [in /home/vitaly/microblog/app/__init__.py:89]
2018-05-10 14:33:21,065 INFO: Microblog startup [in /home/vitaly/microblog/app/__init__.py:89]
2018-05-10 14:33:21,065 INFO: Microblog startup [in /home/vitaly/microblog/app/__init__.py:89]
2018-05-10 14:33:21,066 INFO: Microblog startup [in /home/vitaly/microblog/app/__init__.py:89]
2018-05-10 14:33:21,070 INFO: Microblog startup [in /home/vitaly/microblog/app/__init__.py:89]
2018-05-10 14:36:36,986 INFO: Microblog startup [in /home/vitaly/microblog/app/__init__.py:89]
2018-05-10 14:36:37,252 INFO: Microblog startup [in /home/vitaly/microblog/app/__init__.py:89]
2018-05-10 14:36:37,323 INFO: Microblog startup [in /home/vitaly/microblog/app/__init__.py:89]
2018-05-10 14:36:37,356 INFO: Microblog startup [in /home/vitaly/microblog/app/__init__.py:89]
2018-05-10 14:50:46,372 INFO: Microblog startup [in /home/vitaly/microblog/app/__init__.py:89]
2018-05-10 14:50:46,372 INFO: Microblog startup [in /home/vitaly/microblog/app/__init__.py:89]
2018-05-10 14:50:46,372 INFO: Microblog startup [in /home/vitaly/microblog/app/__init__.py:89]
2018-05-10 14:50:46,373 INFO: Microblog startup [in /home/vitaly/microblog/app/__init__.py:89]
